<mujoco model="fairino_fr5">
    <compiler angle="radian"/>
    <actuator>
        <motor ctrllimited="true" ctrlrange="-150 150" joint="j1" name="torq_j1"/>
        <motor ctrllimited="true" ctrlrange="-150 150" joint="j2" name="torq_j2"/>
        <motor ctrllimited="true" ctrlrange="-100 100" joint="j3" name="torq_j3"/>
        <motor ctrllimited="true" ctrlrange="-50 50" joint="j4" name="torq_j4"/>
        <motor ctrllimited="true" ctrlrange="-50 50" joint="j5" name="torq_j5"/>
        <motor ctrllimited="true" ctrlrange="-30 30" joint="j6" name="torq_j6"/>
    </actuator>
    <asset>
        <mesh name="base_link" file="meshes/base_link.STL"/>
        <mesh name="shoulder_link" file="meshes/shoulder_link.STL"/>
        <mesh name="upperarm_link" file="meshes/upperarm_link.STL"/>
        <mesh name="forearm_link" file="meshes/forearm_link.STL"/>
        <mesh name="wrist1_link" file="meshes/wrist1_link.STL"/>
        <mesh name="wrist2_link" file="meshes/wrist2_link.STL"/>
        <mesh name="wrist3_link" file="meshes/wrist3_link.STL"/>
    </asset>
    <worldbody>
        <body name="base" pos="0 0 0">
            <!-- robot view -->
            <camera mode="fixed" name="robotview" pos="1.0 0 0.4" quat="0.653 0.271 0.271 0.653"/>
            <inertial diaginertia="0 0 0" mass="0" pos="0 0 0"/>
            <!-- mount attached here -->
            <body name="fixed_base_link" pos="0 0 0">
                <site name="right_center" pos="0 0 0.05" size="0.01" rgba="1 0.3 0.3 1" group="2"/>
                <geom type="mesh" mesh="base_link" name="base_geom"/>
                <geom type="mesh" mesh="base_link" group="1" contype="0" conaffinity="0" rgba="0.7 0.7 0.7 1"/>

                <body name="shoulder_link" pos="0 0 0.01">
                    <inertial pos="5.0029e-07 -0.0040922 0.14629" quat="0.999588 0.0287044 7.54149e-06 -1.58789e-05" mass="4.3771" diaginertia="0.010731 0.0104154 0.00817191"/>
                    <joint name="j1" pos="0 0 0" axis="0 0 1" range="-3.0543 3.0543" ref="3.14159" limited="true" />
                    <geom type="mesh" mesh="shoulder_link" name="shoulder_geom" />
                    <geom type="mesh" mesh="shoulder_link" group="1" contype="0" conaffinity="0" rgba="1 0 0 1"/>
                    
                    <body name="upperarm_link" pos="0 0 0.152" quat="0.707105 0.707108 0 0">
                        <inertial pos="-0.2125 -5.7643e-09 0.1346" quat="0.5 0.5 0.5 0.5" mass="14.458" diaginertia="0.4559 0.44974 0.028392"/>
                        <joint name="j2" pos="0 0 0" axis="0 0 1" range="-4.6251 1.4835" limited="true" />
                        <geom type="mesh" mesh="upperarm_link" name="upperarm_geom"/>
                        <geom type="mesh" mesh="upperarm_link" group="1" contype="0" conaffinity="0" rgba="0 1 0 1"/>
                        
                        <body name="forearm_link" pos="-0.425 0 0">
                            <inertial pos="-0.18793 -8.4503e-07 0.0066357" quat="0.510607 0.489172 0.489196 0.510568" mass="7.6737" diaginertia="0.16971 0.168834 0.00821541"/>
                            <joint name="j3" pos="0 0 0" axis="0 0 1" range="-2.8274 2.8274" limited="true" />
                            <geom type="mesh" mesh="forearm_link" name="forearm_geom"/>
                            <geom type="mesh" mesh="forearm_link" group="1" contype="0" conaffinity="0" rgba="0 0 1 1"/>
                            
                            <body name="wrist1_link" pos="-0.39501 0 0">
                                <inertial pos="4.98e-07 -0.003754 0.097155" quat="0.736149 0.676819 -6.33095e-05 7.15237e-05" mass="1.6266" diaginertia="0.00216 0.00199337 0.00154233"/>
                                <joint name="j4" pos="0 0 0" axis="0 0 1" range="-4.6251 1.4835" limited="true" />
                                <geom type="mesh" mesh="wrist1_link" name="wrist1_geom"/>
                                <geom type="mesh" mesh="wrist1_link" group="1" contype="0" conaffinity="0" rgba="1 1 1 1"/>
                                
                                <body name="wrist2_link" pos="0 0 0.1021" quat="0.707105 0.707108 0 0">
                                    <inertial pos="-4.5588e-07 0.0038617 0.098257" quat="0.68712 0.726544 0.000128667 -0.000114125" mass="1.5812" diaginertia="0.0020612 0.00195889 0.00144611"/>
                                    <joint name="j5" pos="0 0 0" axis="0 0 1" range="-3.0543 3.0543" limited="true" />
                                    <geom type="mesh" mesh="wrist2_link" name="wrist2_geom"/>
                                    <geom type="mesh" mesh="wrist2_link" group="1" contype="0" conaffinity="0" rgba="0.7 0.7 0.7 1"/>
                                    
                                    <body name="wrist3_link" pos="0 0 0.102" quat="0.707105 -0.707108 0 0">
                                        <inertial pos="7.7496e-05 1.7751e-05 0.076122" quat="7.93213e-05 0.706804 0.00108234 0.707408" mass="0.52542" diaginertia="0.00041605 0.00027839 0.00027721"/>
                                        <joint name="j6" pos="0 0 0" axis="0 0 1" range="-3.0543 3.0543" limited="true" />
                                        <geom type="mesh" mesh="wrist3_link" name="wrist3_geom"/>
                                        <geom type="mesh" mesh="wrist3_link" group="1" contype="0" conaffinity="0" rgba="0.7 0.7 0.7 1"/>
                                        <body name="right_hand" pos="0 0 0.05" quat="0 0 0 1">
                                            <camera mode="fixed"  name="eye_in_hand" pos="0.05 0 0" quat="0 0.707107 0 0.707107" fovy="75"/>
                                        </body>
                                    </body>
                                </body>
                            </body>
                        </body>
                    </body>
                </body>
            </body>
        </body>
    </worldbody>
</mujoco>